Workbook

Sheet Instructions
A1: GC Investment Tracker — Read This First
A3: Welcome
A4: This tracker is the source of truth for the GC Private Markets Dashboard. Enter your deals here, save the file, and drag it onto the dashboard. Three tabs do the work — Investments, GC_Framework, and CashFlows. The other tabs (Pivot_Summary, Dashboard, Lists, CashFlow_Chart) are auto-calculated; you don't need to touch them.
A6: How the cell colors work
A7: Yellow cells: enter your data here.
A8: Grey cells: formulas that auto-calculate. Don't edit them — they're locked to prevent accidental changes.
A9: Green cells: optional fields like Notes and Contact info. Helpful for your own records but not required.
A11: Quick start — adding your first deal (8 minutes)
A12: 1. Decide if you want to keep the example data. If not, select rows 7–18 on the Investments sheet, right-click, choose Clear Contents (NOT Delete Row — that would shift formulas around). Do the same on the GC_Framework sheet for rows 5–16.
A13: 2. On the Investments sheet, go to row 7 (or the first empty row after your existing data). Fill in the yellow cells:
A14: • A: Deal ID — your own internal code, e.g. GC-RE-001 or PROP-2024-01. Make it unique and don't change it later (it links to GC_Framework).
A15: • B: Deal Name — what the sponsor calls it.
... A56: Post in the Growth Circle forum thread or DM the maintainer. Bring a screenshot of the issue.

Sheet Investments
A1: Investments
A2: COLOR LEGEND: | B2: Yellow = enter your data here | E2: Grey = auto-calculated, do not edit | I2: Green = optional but recommended
A3: How to use: enter your deals starting at row 7. The yellow cells are the ones you fill in. Grey cells auto-fill from your inputs — leave them alone. Don't change Deal IDs after creating them; they link to the GC_Framework sheet. To delete the example deals, select rows 7-18, right-click, "Clear Contents".
A6: Deal ID | B6: Deal Name | C6: Sponsor/Manager | D6: Asset Class | E6: VS Stage | F6: Portfolio Role | G6: Deal Status | H6: Sub-Strategy | I6: Vehicle Type | J6: Account Type | K6: Entity/Title | L6: Tax Bucket (est.) | M6: Date Committed | N6: Date Funded | O6: Commitment ($) | P6: Amount Funded ($) | Q6: Unfunded ($) | R6: Capital Call Schedule | S6: Lockup (yrs) | T6: Target Horizon (yrs) | U6: Current Value ($) | V6: Distributions ($) | W6: Distribution Schedule/Notes | X6: Total Value ($) | Y6: Anticipated Value ($) | Z6: Expected ARR | AA6: Expected MOIC | AB6: Actual MOIC | AC6: Notes | AD6: Contact | AE6: Contact Info
A7: GC-RE-001 | B7: Eephus Growth Fund I | C7: EEPHUS GROWTH FUND, LLC | D7: Real Estate | E7: NA | F7: R2-Anchor Income + Tax Shield | G7: Closed | H7: Real Estate / Syndicated | I7: Fund | J7: SD-IRA | K7: Individual | L7: Passive | M7: 45867 | N7: 45873 | O7: 50000 | P7: 50000 | Q7: =IF(OR(O7="",P7=""),"",O7-P7) -> 0 | R7: NA | S7: 5 | T7: 7 | U7: 50000 | V7: 0 | W7: Quarterly - 6% starting 6/1/2026. $750 per quarter expected starting on 6/1/2026. | X7: =IF(OR(U7="",V7=""),"",U7+V7) -> 50000 | Y7: =tblInvestments[[#This Row],[Commitment ($)]]*tblInvestments[[#This Row],[Expected MOIC]] -> 90000 | Z7: 0.16 | AA7: 1.8 | AB7: =IFERROR(X7/P7,"") -> 1 | AD7: Bo Burrup | AE7: 208-417-9297
A8: GC-PE-001 | B8: BlueBird Capital (Tranche 1) | C8: BLUEBIRD CAPITAL GROUP, LP | D8: Private Equity | E8: NA | F8: R4-Operational Value-Add / Cash-Flowing PE | G8: Closed | H8: Private Equity / Special Situations | I8: Fund | J8: SD-IRA | K8: Individual | L8: Passive | M8: 45890 | N8: 45903 | O8: 50000 | P8: 50000 | Q8: =IF(OR(O8="",P8=""),"",O8-P8) -> 0 | R8: NA | S8: 5 | T8: 7 | U8: 50000 | V8: 0 | W8: Annual - 15% at funding anniversary date. $7500 on September 3rd starting in 2026 | X8: =IF(OR(U8="",V8=""),"",U8+V8) -> 50000 | Y8: =tblInvestments[[#This Row],[Commitment ($)]]*tblInvestments[[#This Row],[Expected MOIC]] -> 132500 | Z8: 0.2 | AA8: 2.65 | AB8: =IFERROR(X8/P8,"") -> 1 | AD8: Braydon Lee | AE8: 208-573-1202
A9: GC-VC-001 | B9: Next Life Sciences - Plan A | C9: Spacestation 87, a series of Spacestation Investments 1, LLC | D9: VC | E9: Seed | F9: R8-Asymetric Moonshot/Binary Catalyst | G9: Closed | H9: Healthcare / MedTech | I9: SPV | J9: SD-IRA | K9: Individual | L9: Portfolio | M9: 45901 | N9: 45915 | O9: 10000 | P9: 10000 | Q9: =IF(OR(O9="",P9=""),"",O9-P9) -> 0 | R9: NA | S9: 10 | T9: 10 | U9: 10000 | V9: 0 | W9: NA | X9: =IF(OR(U9="",V9=""),"",U9+V9) -> 10000 | Y9: =tblInvestments[[#This Row],[Commitment ($)]]*tblInvestments[[#This Row],[Expected MOIC]] -> 40000 | AA9: 4 | AB9: =IFERROR(X9/P9,"") -> 1 | AD9: Timothy Holladay | AE9: 480-734-8232
A10: GC-VC-002 | B10: Telly TV | C10: Spacestation 88, a series of Spacestation Investments 1, LLC | D10: VC | E10: Series A | F10: R7-Platform-Scale VC (High Beta) | G10: Closed | H10: Consumer / Ad-Supported Hardware | I10: SPV | J10: SD-IRA | K10: Individual | L10: Portfolio | M10: 45931 | N10: 45945 | O10: 5000 | P10: 5000 | Q10: =IF(OR(O10="",P10=""),"",O10-P10) -> 0 | R10: NA | S10: 10 | T10: 10 | U10: 5000 | V10: 0 | W10: NA | X10: =IF(OR(U10="",V10=""),"",U10+V10) -> 5000 | Y10: =tblInvestments[[#This Row],[Commitment ($)]]*tblInvestments[[#This Row],[Expected MOIC]] -> 8900 | AA10: 1.78 | AB10: =IFERROR(X10/P10,"") -> 1 | AD10: Timothy Holladay | AE10: 480-734-8232
A11: GC-VC-003 | B11: ÆRTHLINGS | C11: Spacestation 89, a series of Spacestation Investments 1, LLC | D11: VC | E11: Seed | F11: R6-Franchise/Category IP Upside | G11: Closed | H11: Consumer / Brand | I11: SPV | J11: SD-IRA | K11: Individual | L11: Portfolio | M11: 45962 | N11: 45971 | O11: 10000 | P11: 10000 | Q11: =IF(OR(O11="",P11=""),"",O11-P11) -> 0 | R11: NA | S11: 10 | T11: 10 | U11: 10000 | V11: 0 | W11: NA | X11: =IF(OR(U11="",V11=""),"",U11+V11) -> 10000 | Y11: =tblInvestments[[#This Row],[Commitment ($)]]*tblInvestments[[#This Row],[Expected MOIC]] -> 100000 | AA11: 10 | AB11: =IFERROR(X11/P11,"") -> 1 | AD11: Timothy Holladay | AE11: 480-734-8232
A12: GC-VC-004 | B12: SpaceStation Fund | C12: SPVC VENTURES FUND I, L.P. AND SPVC VENTURES FUND I Q, L.P. | D12: VC | E12: Fund | F12: R7-Platform-Scale VC (High Beta) | G12: Opened | H12: Consumer / Tech-Enabled | I12: Fund | J12: SD-IRA | K12: Individual | L12: Portfolio | M12: 45901 | N12: 45915 | O12: 250000 | P12: 50000 | Q12: =IF(OR(O12="",P12=""),"",O12-P12) -> 200000 | R12: Quarterly - $12,500 continuing on 5/22/2026 | S12: 10 | T12: 10 | U12: =tblInvestments[[#This Row],[Amount Funded ($)]] -> 50000 | V12: 0 | W12: NA | X12: =IF(OR(U12="",V12=""),"",U12+V12) -> 50000 | Y12: =tblInvestments[[#This Row],[Commitment ($)]]*tblInvestments[[#This Row],[Expected MOIC]] -> 985000 | AA12: 3.94 | AB12: =IFERROR(X12/P12,"") -> 1 | AD12: Timothy Holladay | AE12: 480-734-8232
A13: GC-VC-005 | B13: Turbo Insurance | C13: Amplifi Turbo LLC | D13: VC | E13: Seed | F13: R7-Platform-Scale VC (High Beta) | G13: Closed | H13: Private Equity (AI x Insurtech Growth Capital Raise) | I13: SPV | J13: SD-IRA | K13: Individual | L13: Portfolio | M13: 46287 | N13: 46287 | O13: 20000 | P13: 20000 | Q13: =IF(OR(O13="",P13=""),"",O13-P13) -> 0 | R13: NA | S13: 5 | T13: 5 | U13: 20000 | V13: 0 | W13: NA | X13: =IF(OR(U13="",V13=""),"",U13+V13) -> 20000 | Y13: =tblInvestments[[#This Row],[Commitment ($)]]*tblInvestments[[#This Row],[Expected MOIC]] -> 100000 | Z13: 0.8 | AA13: 5 | AB13: =IFERROR(X13/P13,"") -> 1 | AC13: Private Equity (AI x Insurtech Growth Capital Raise) | AD13: Myles Johnson | AE13: 602-807-1915
A14: GC-RE-002 | B14: Eephus Growth Fund II | C14: EEPHUS GROWTH FUND, LLC | D14: Real Estate | E14: NA | F14: R2-Anchor Income + Tax Shield | G14: Opened | H14: Real Estate / Syndicated | I14: Fund | J14: SD-IRA | K14: Individual | L14: Passive | M14: 46052 | N14: 46070 | O14: 50000 | P14: 50000 | Q14: =IF(OR(O14="",P14=""),"",O14-P14) -> 0 | R14: NA | S14: 5 | T14: 7 | U14: 50000 | V14: 0 | W14: Quarterly - 6% annual starting 2/1/2027. $750 per quarter expected starting on 2/1/2027 | X14: =IF(OR(U14="",V14=""),"",U14+V14) -> 50000 | Y14: =tblInvestments[[#This Row],[Commitment ($)]]*tblInvestments[[#This Row],[Expected MOIC]] -> 87500 | Z14: 0.15 | AA14: 1.75 | AB14: =IFERROR(X14/P14,"") -> 1 | AD14: Bo Burrup | AE14: 208-417-9297
A15: GC-PE-002 | B15: BlueBird Capital (Tranche 2) | C15: BLUEBIRD CAPITAL GROUP, LP | D15: Private Equity | E15: NA | F15: R4-Operational Value-Add / Cash-Flowing PE | G15: Closed | H15: Private Equity / Special Situations | I15: Fund | J15: SD-IRA | K15: Individual | L15: Passive | M15: 46064 | N15: 46071 | O15: 50000 | P15: 50000 | Q15: =IF(OR(O15="",P15=""),"",O15-P15) -> 0 | R15: NA | S15: 5 | T15: 7 | U15: 50000 | V15: 0 | W15: Annual - 15% at funding anniversary date. $7500 on February 18th starting in 2027 | X15: =IF(OR(U15="",V15=""),"",U15+V15) -> 50000 | Y15: =tblInvestments[[#This Row],[Commitment ($)]]*tblInvestments[[#This Row],[Expected MOIC]] -> 132500 | Z15: 0.2 | AA15: 2.65 | AB15: =IFERROR(X15/P15,"") -> 1 | AD15: Braydon Lee | AE15: 208-573-1202
A16: GC-VC-006 | B16: Aerolane | C16: Spacestation | D16: VC | F16: R8-Asymetric Moonshot/Binary Catalyst | G16: Closed | H16: Aerospace / Logistics Infrastructure | I16: SPV | J16: SD-IRA | K16: Individual | L16: Portfolio | M16: 46098 | N16: 46116 | O16: 25000 | P16: 25000 | Q16: =IF(OR(O16="",P16=""),"",O16-P16) -> 0 | R16: NA | S16: 5 | T16: 10 | U16: 25000 | V16: 0 | W16: NA | X16: =IF(OR(U16="",V16=""),"",U16+V16) -> 25000 | Y16: =tblInvestments[[#This Row],[Commitment ($)]]*tblInvestments[[#This Row],[Expected MOIC]] -> 250000 | AA16: 10 | AB16: =IFERROR(X16/P16,"") -> 1 | AD16: Belltower Fund Group, Ltd. | AE16: 425-310-2445
A17: GC-VC-007 | B17: Rorra | C17: Spacestation | D17: VC | E17: Pre-Seed | F17: R6 — Franchise / Category IP | G17: Closed | H17: Consumer | I17: SPV | J17: SD-IRA | K17: Individual | L17: Portfolio | M17: 46121 | N17: 46129 | O17: 10000 | P17: 10000 | Q17: =IF(OR(O17="",P17=""),"",O17-P17) -> 0 | R17: NA | S17: 10 | T17: 10 | U17: 10000 | V17: 0 | W17: NA | X17: =IF(OR(U17="",V17=""),"",U17+V17) -> 10000 | Y17: =tblInvestments[[#This Row],[Commitment ($)]]*tblInvestments[[#This Row],[Expected MOIC]] -> 27100 | AA17: 2.71 | AB17: =IFERROR(X17/P17,"") -> 1 | AD17: Belltower Fund Group, Ltd. | AE17: 425-310-2445
A18: GC-PE-003 | B18: Asilia GC Fund | C18: Asilia | D18: Private Credit | E18: NA | F18: R3 — High-Yield Private | G18: Opened | H18: Private Credit | I18: Fund | J18: SD-IRA | K18: Individual | L18: Passive | M18: 46135 | N18: 46174 | O18: 100000 | P18: 10000 | Q18: =IF(OR(O18="",P18=""),"",O18-P18) -> 90000 | R18: Quarterly - $10,000. Initial $10,000 on funding date (6/1/2026). $10,000 per quarter starting on 9/1/2026 | S18: 8 | T18: 8 | U18: =tblInvestments[[#This Row],[Amount Funded ($)]] -> 10000 | V18: 0 | W18: Quarterly - 12% annual starting on 6/1/2027 (approx.). $3000 per quarter starting on 6/1/2027. | X18: =IF(OR(U18="",V18=""),"",U18+V18) -> 10000 | Y18: =tblInvestments[[#This Row],[Commitment ($)]]*tblInvestments[[#This Row],[Expected MOIC]] -> 327000 | Z18: 0.23 | AA18: 3.27 | AB18: =IFERROR(X18/P18,"") -> 1
Q19: =IF(OR(O19="",P19=""),"",O19-P19) | X19: =IF(OR(U19="",V19=""),"",U19+V19) | Y19: =IF(OR(O19="",AA19=""),"",O19*AA19) | AA19: =IFERROR(Y19/P19,"") | AB19: =IFERROR(X19/P19,"")
Q20: =IF(OR(O20="",P20=""),"",O20-P20) | X20: =IF(OR(U20="",V20=""),"",U20+V20) | Y20: =IF(OR(O20="",AA20=""),"",O20*AA20) | AA20: =IFERROR(Y20/P20,"") | AB20: =IFERROR(X20/P20,"")
Q21: =IF(OR(O21="",P21=""),"",O21-P21) | X21: =IF(OR(U21="",V21=""),"",U21+V21) | Y21: =IF(OR(O21="",AA21=""),"",O21*AA21) | AA21: =IFERROR(Y21/P21,"") | AB21: =IFERROR(X21/P21,"")
Q22: =IF(OR(O22="",P22=""),"",O22-P22) | X22: =IF(OR(U22="",V22=""),"",U22+V22) | Y22: =IF(OR(O22="",AA22=""),"",O22*AA22) | AA22: =IFERROR(Y22/P22,"") | AB22: =IFERROR(X22/P22,"")
Q23: =IF(OR(O23="",P23=""),"",O23-P23) | X23: =IF(OR(U23="",V23=""),"",U23+V23) | Y23: =IF(OR(O23="",AA23=""),"",O23*AA23) | AA23: =IFERROR(Y23/P23,"") | AB23: =IFERROR(X23/P23,"")
Q24: =IF(OR(O24="",P24=""),"",O24-P24) | X24: =IF(OR(U24="",V24=""),"",U24+V24) | Y24: =IF(OR(O24="",AA24=""),"",O24*AA24) | AA24: =IFERROR(Y24/P24,"") | AB24: =IFERROR(X24/P24,"")
Q25: =IF(OR(O25="",P25=""),"",O25-P25) | X25: =IF(OR(U25="",V25=""),"",U25+V25) | Y25: =IF(OR(O25="",AA25=""),"",O25*AA25) | AA25: =IFERROR(Y25/P25,"") | AB25: =IFERROR(X25/P25,"")
Q26: =IF(OR(O26="",P26=""),"",O26-P26) | X26: =IF(OR(U26="",V26=""),"",U26+V26) | Y26: =IF(OR(O26="",AA26=""),"",O26*AA26) | AA26: =IFERROR(Y26/P26,"") | AB26: =IFERROR(X26/P26,"")
Q27: =IF(OR(O27="",P27=""),"",O27-P27) | X27: =IF(OR(U27="",V27=""),"",U27+V27) | Y27: =IF(OR(O27="",AA27=""),"",O27*AA27) | AA27: =IFERROR(Y27/P27,"") | AB27: =IFERROR(X27/P27,"")
Q28: =IF(OR(O28="",P28=""),"",O28-P28) | X28: =IF(OR(U28="",V28=""),"",U28+V28) | Y28: =IF(OR(O28="",AA28=""),"",O28*AA28) | AA28: =IFERROR(Y28/P28,"") | AB28: =IFERROR(X28/P28,"")
Q29: =IF(OR(O29="",P29=""),"",O29-P29) | X29: =IF(OR(U29="",V29=""),"",U29+V29) | Y29: =IF(OR(O29="",AA29=""),"",O29*AA29) | AA29: =IFERROR(Y29/P29,"") | AB29: =IFERROR(X29/P29,"")
Q30: =IF(OR(O30="",P30=""),"",O30-P30) | X30: =IF(OR(U30="",V30=""),"",U30+V30) | Y30: =IF(OR(O30="",AA30=""),"",O30*AA30) | AA30: =IFERROR(Y30/P30,"") | AB30: =IFERROR(X30/P30,"")
... Q56: =IF(OR(O56="",P56=""),"",O56-P56) | X56: =IF(OR(U56="",V56=""),"",U56+V56) | Y56: =IF(OR(O56="",AA56=""),"",O56*AA56) | AA56: =IFERROR(Y56/P56,"") | AB56: =IFERROR(X56/P56,"")
Q57: =IF(OR(O57="",P57=""),"",O57-P57) | X57: =IF(OR(U57="",V57=""),"",U57+V57) | Y57: =IF(OR(O57="",AA57=""),"",O57*AA57) | AB57: =IFERROR(X57/P57,"")
Q58: =IF(OR(O58="",P58=""),"",O58-P58) | X58: =IF(OR(U58="",V58=""),"",U58+V58) | Y58: =IF(OR(O58="",AA58=""),"",O58*AA58) | AB58: =IFERROR(X58/P58,"")
Q59: =IF(OR(O59="",P59=""),"",O59-P59) | X59: =IF(OR(U59="",V59=""),"",U59+V59) | Y59: =IF(OR(O59="",AA59=""),"",O59*AA59) | AB59: =IFERROR(X59/P59,"")
Q60: =IF(OR(O60="",P60=""),"",O60-P60) | X60: =IF(OR(U60="",V60=""),"",U60+V60) | Y60: =IF(OR(O60="",AA60=""),"",O60*AA60) | AB60: =IFERROR(X60/P60,"")
Q61: =IF(OR(O61="",P61=""),"",O61-P61) | X61: =IF(OR(U61="",V61=""),"",U61+V61) | Y61: =IF(OR(O61="",AA61=""),"",O61*AA61) | AB61: =IFERROR(X61/P61,"")
Q62: =IF(OR(O62="",P62=""),"",O62-P62) | X62: =IF(OR(U62="",V62=""),"",U62+V62) | Y62: =IF(OR(O62="",AA62=""),"",O62*AA62) | AB62: =IFERROR(X62/P62,"")
Q63: =IF(OR(O63="",P63=""),"",O63-P63) | X63: =IF(OR(U63="",V63=""),"",U63+V63) | Y63: =IF(OR(O63="",AA63=""),"",O63*AA63) | AB63: =IFERROR(X63/P63,"")
Q64: =IF(OR(O64="",P64=""),"",O64-P64) | X64: =IF(OR(U64="",V64=""),"",U64+V64) | Y64: =IF(OR(O64="",AA64=""),"",O64*AA64) | AB64: =IFERROR(X64/P64,"")
Q65: =IF(OR(O65="",P65=""),"",O65-P65) | X65: =IF(OR(U65="",V65=""),"",U65+V65) | Y65: =IF(OR(O65="",AA65=""),"",O65*AA65) | AB65: =IFERROR(X65/P65,"")
Q66: =IF(OR(O66="",P66=""),"",O66-P66) | X66: =IF(OR(U66="",V66=""),"",U66+V66) | Y66: =IF(OR(O66="",AA66=""),"",O66*AA66) | AB66: =IFERROR(X66/P66,"")
Q67: =IF(OR(O67="",P67=""),"",O67-P67) | X67: =IF(OR(U67="",V67=""),"",U67+V67) | Y67: =IF(OR(O67="",AA67=""),"",O67*AA67) | AB67: =IFERROR(X67/P67,"")
...

Sheet CashFlows
A1: CashFlows — Event Log
A2: COLOR LEGEND: | B2: Yellow = enter your data | E2: Grey = auto-calculated
A3: How to use: each row is one cashflow event (a capital call, distribution, fee, etc.). Enter Date, Deal Name, Account Type, Flow Type, and Amount. The Call Type column auto-classifies. Use negative amounts for outflows (capital calls, fees) and positive for inflows (distributions). Add new rows below the existing ones — there's capacity for 300+ events.
A5: Date | B5: Deal Name | C5: Account Type | D5: Flow Type | E5: Amount ($) | F5: Notes | G5: Call Type | H5: Column2
A6: 45873 | B6: Eephus Growth Fund I | C6: SD-IRA | D6: Capital Call | E6: -50000 | G6: =IF($D6="Capital Call",IF(SUMPRODUCT(($B$6:$B6=$B6)*($D$6:$D6="Capital Call"))=1,"Initial","Ongoing"),"") -> Initial
A7: 45903 | B7: BlueBird Capital (Tranche 1) | C7: SD-IRA | D7: Capital Call | E7: -50000 | G7: =IF($D7="Capital Call",IF(SUMPRODUCT(($B$6:$B7=$B7)*($D$6:$D7="Capital Call"))=1,"Initial","Ongoing"),"") -> Initial
A8: 45915 | B8: Next Life Sciences - Plan A | C8: SD-IRA | D8: Capital Call | E8: -10000 | G8: =IF($D8="Capital Call",IF(SUMPRODUCT(($B$6:$B8=$B8)*($D$6:$D8="Capital Call"))=1,"Initial","Ongoing"),"") -> Initial
A9: 45945 | B9: Telly TV | C9: SD-IRA | D9: Capital Call | E9: -5000 | G9: =IF($D9="Capital Call",IF(SUMPRODUCT(($B$6:$B9=$B9)*($D$6:$D9="Capital Call"))=1,"Initial","Ongoing"),"") -> Initial
A10: 45971 | B10: ÆRTHLINGS | C10: SD-IRA | D10: Capital Call | E10: -10000 | G10: =IF($D10="Capital Call",IF(SUMPRODUCT(($B$6:$B10=$B10)*($D$6:$D10="Capital Call"))=1,"Initial","Ongoing"),"") -> Initial
A11: 45915 | B11: SpaceStation Fund | C11: SD-IRA | D11: Capital Call | E11: -50000 | G11: =IF($D11="Capital Call",IF(SUMPRODUCT(($B$6:$B11=$B11)*($D$6:$D11="Capital Call"))=1,"Initial","Ongoing"),"") -> Initial
A12: 46287 | B12: Turbo Insurance | C12: SD-IRA | D12: Capital Call | E12: -20000 | G12: =IF($D12="Capital Call",IF(SUMPRODUCT(($B$6:$B12=$B12)*($D$6:$D12="Capital Call"))=1,"Initial","Ongoing"),"") -> Initial
A13: 46070 | B13: Eephus Growth Fund II | C13: SD-IRA | D13: Capital Call | E13: -50000 | G13: =IF($D13="Capital Call",IF(SUMPRODUCT(($B$6:$B13=$B13)*($D$6:$D13="Capital Call"))=1,"Initial","Ongoing"),"") -> Initial
A14: 46071 | B14: BlueBird Capital (Tranche 2) | C14: SD-IRA | D14: Capital Call | E14: -50000 | G14: =IF($D14="Capital Call",IF(SUMPRODUCT(($B$6:$B14=$B14)*($D$6:$D14="Capital Call"))=1,"Initial","Ongoing"),"") -> Initial
A15: 46116 | B15: Aerolane | C15: SD-IRA | D15: Capital Call | E15: -25000 | G15: =IF($D15="Capital Call",IF(SUMPRODUCT(($B$6:$B15=$B15)*($D$6:$D15="Capital Call"))=1,"Initial","Ongoing"),"") -> Initial
A16: 46129 | B16: Rorra | C16: SD-IRA | D16: Capital Call | E16: -10000 | G16: =IF($D16="Capital Call",IF(SUMPRODUCT(($B$6:$B16=$B16)*($D$6:$D16="Capital Call"))=1,"Initial","Ongoing"),"") -> Initial
A17: 46164 | B17: SpaceStation Fund | C17: SD-IRA | D17: Capital Call | E17: -12500 | G17: =IF($D17="Capital Call",IF(SUMPRODUCT(($B$6:$B17=$B17)*($D$6:$D17="Capital Call"))=1,"Initial","Ongoing"),"") -> Ongoing
... A119: 48628 | B119: BlueBird Capital (Tranche 2) | C119: SD-IRA | D119: Capital at Exit | E119: 80000 | G119: =IF($D119="Capital Call",IF(SUMPRODUCT(($B$6:$B119=$B119)*($D$6:$D119="Capital Call"))=1,"Initial","Ongoing"),"")
G120: =IF($D120="Capital Call",IF(SUMPRODUCT(($B$6:$B120=$B120)*($D$6:$D120="Capital Call"))=1,"Initial","Ongoing"),"")
G121: =IF($D121="Capital Call",IF(SUMPRODUCT(($B$6:$B121=$B121)*($D$6:$D121="Capital Call"))=1,"Initial","Ongoing"),"")
G122: =IF($D122="Capital Call",IF(SUMPRODUCT(($B$6:$B122=$B122)*($D$6:$D122="Capital Call"))=1,"Initial","Ongoing"),"")
G123: =IF($D123="Capital Call",IF(SUMPRODUCT(($B$6:$B123=$B123)*($D$6:$D123="Capital Call"))=1,"Initial","Ongoing"),"")
G124: =IF($D124="Capital Call",IF(SUMPRODUCT(($B$6:$B124=$B124)*($D$6:$D124="Capital Call"))=1,"Initial","Ongoing"),"")
G125: =IF($D125="Capital Call",IF(SUMPRODUCT(($B$6:$B125=$B125)*($D$6:$D125="Capital Call"))=1,"Initial","Ongoing"),"")
G126: =IF($D126="Capital Call",IF(SUMPRODUCT(($B$6:$B126=$B126)*($D$6:$D126="Capital Call"))=1,"Initial","Ongoing"),"")
G127: =IF($D127="Capital Call",IF(SUMPRODUCT(($B$6:$B127=$B127)*($D$6:$D127="Capital Call"))=1,"Initial","Ongoing"),"")
G128: =IF($D128="Capital Call",IF(SUMPRODUCT(($B$6:$B128=$B128)*($D$6:$D128="Capital Call"))=1,"Initial","Ongoing"),"")
G129: =IF($D129="Capital Call",IF(SUMPRODUCT(($B$6:$B129=$B129)*($D$6:$D129="Capital Call"))=1,"Initial","Ongoing"),"")
G130: =IF($D130="Capital Call",IF(SUMPRODUCT(($B$6:$B130=$B130)*($D$6:$D130="Capital Call"))=1,"Initial","Ongoing"),"")
G131: =IF($D131="Capital Call",IF(SUMPRODUCT(($B$6:$B131=$B131)*($D$6:$D131="Capital Call"))=1,"Initial","Ongoing"),"")
... G309: =IF($D309="Capital Call",IF(SUMPRODUCT(($B$6:$B309=$B309)*($D$6:$D309="Capital Call"))=1,"Initial","Ongoing"),"")

Sheet Pivot_Summary
A1: Pivot_Summary (formula-based)
A2: These summaries are powered by SUMIFS (works without Excel PivotTables/macros).
A4: By Asset Class
A6: Asset Class | B6: Committed | C6: Funded | D6: Current Value | E6: Distributions | F6: MOIC (weighted)
A7: VC | B7: =SUMIFS(Investments!$O$7:$O$206,Investments!$D$7:$D$206,$A7,Investments!$J$7:$J$206,IF(Dashboard!$B$6="All","*",Dashboard!$B$6)) -> 330000 | C7: =SUMIFS(Investments!$P$7:$P$206,Investments!$D$7:$D$206,$A7,Investments!$J$7:$J$206,IF(Dashboard!$B$6="All","*",Dashboard!$B$6)) -> 130000 | D7: =SUMIFS(Investments!$U$7:$U$206,Investments!$D$7:$D$206,$A7,Investments!$J$7:$J$206,IF(Dashboard!$B$6="All","*",Dashboard!$B$6)) -> 130000 | E7: =SUMIFS(Investments!$V$7:$V$206,Investments!$D$7:$D$206,$A7,Investments!$J$7:$J$206,IF(Dashboard!$B$6="All","*",Dashboard!$B$6)) -> 0 | F7: =IFERROR(($D7+$E7)/$C7,"") -> 1
A8: Private Equity | B8: =SUMIFS(Investments!$O$7:$O$206,Investments!$D$7:$D$206,$A8,Investments!$J$7:$J$206,IF(Dashboard!$B$6="All","*",Dashboard!$B$6)) -> 100000 | C8: =SUMIFS(Investments!$P$7:$P$206,Investments!$D$7:$D$206,$A8,Investments!$J$7:$J$206,IF(Dashboard!$B$6="All","*",Dashboard!$B$6)) -> 100000 | D8: =SUMIFS(Investments!$U$7:$U$206,Investments!$D$7:$D$206,$A8,Investments!$J$7:$J$206,IF(Dashboard!$B$6="All","*",Dashboard!$B$6)) -> 100000 | E8: =SUMIFS(Investments!$V$7:$V$206,Investments!$D$7:$D$206,$A8,Investments!$J$7:$J$206,IF(Dashboard!$B$6="All","*",Dashboard!$B$6)) -> 0 | F8: =IFERROR(($D8+$E8)/$C8,"") -> 1
A9: Real Estate | B9: =SUMIFS(Investments!$O$7:$O$206,Investments!$D$7:$D$206,$A9,Investments!$J$7:$J$206,IF(Dashboard!$B$6="All","*",Dashboard!$B$6)) -> 100000 | C9: =SUMIFS(Investments!$P$7:$P$206,Investments!$D$7:$D$206,$A9,Investments!$J$7:$J$206,IF(Dashboard!$B$6="All","*",Dashboard!$B$6)) -> 100000 | D9: =SUMIFS(Investments!$U$7:$U$206,Investments!$D$7:$D$206,$A9,Investments!$J$7:$J$206,IF(Dashboard!$B$6="All","*",Dashboard!$B$6)) -> 100000 | E9: =SUMIFS(Investments!$V$7:$V$206,Investments!$D$7:$D$206,$A9,Investments!$J$7:$J$206,IF(Dashboard!$B$6="All","*",Dashboard!$B$6)) -> 0 | F9: =IFERROR(($D9+$E9)/$C9,"") -> 1
A10: Private Credit | B10: =SUMIFS(Investments!$O$7:$O$206,Investments!$D$7:$D$206,$A10,Investments!$J$7:$J$206,IF(Dashboard!$B$6="All","*",Dashboard!$B$6)) -> 100000 | C10: =SUMIFS(Investments!$P$7:$P$206,Investments!$D$7:$D$206,$A10,Investments!$J$7:$J$206,IF(Dashboard!$B$6="All","*",Dashboard!$B$6)) -> 10000 | D10: =SUMIFS(Investments!$U$7:$U$206,Investments!$D$7:$D$206,$A10,Investments!$J$7:$J$206,IF(Dashboard!$B$6="All","*",Dashboard!$B$6)) -> 10000 | E10: =SUMIFS(Investments!$V$7:$V$206,Investments!$D$7:$D$206,$A10,Investments!$J$7:$J$206,IF(Dashboard!$B$6="All","*",Dashboard!$B$6)) -> 0 | F10: =IFERROR(($D10+$E10)/$C10,"") -> 1
A11: Other | B11: =SUMIFS(Investments!$O$7:$O$206,Investments!$D$7:$D$206,$A11,Investments!$J$7:$J$206,IF(Dashboard!$B$6="All","*",Dashboard!$B$6)) -> 0 | C11: =SUMIFS(Investments!$P$7:$P$206,Investments!$D$7:$D$206,$A11,Investments!$J$7:$J$206,IF(Dashboard!$B$6="All","*",Dashboard!$B$6)) -> 0 | D11: =SUMIFS(Investments!$U$7:$U$206,Investments!$D$7:$D$206,$A11,Investments!$J$7:$J$206,IF(Dashboard!$B$6="All","*",Dashboard!$B$6)) -> 0 | E11: =SUMIFS(Investments!$V$7:$V$206,Investments!$D$7:$D$206,$A11,Investments!$J$7:$J$206,IF(Dashboard!$B$6="All","*",Dashboard!$B$6)) -> 0 | F11: =IFERROR(($D11+$E11)/$C11,"")
A12: TOTAL | B12: =SUM(B7:B11) -> 630000 | C12: =SUM(C7:C11) -> 340000 | D12: =SUM(D7:D11) -> 340000 | E12: =SUM(E7:E11) -> 0 | F12: =IFERROR(($D12+$E12)/$C12,"") -> 1
A14: By Account Type
A16: Account Type | B16: Committed | C16: Funded | D16: Current Value | E16: Distributions
A17: Taxable | B17: =SUMIFS(Investments!$O$7:$O$206,Investments!$J$7:$J$206,$A17) -> 0 | C17: =SUMIFS(Investments!$P$7:$P$206,Investments!$J$7:$J$206,$A17) -> 0 | D17: =SUMIFS(Investments!$U$7:$U$206,Investments!$J$7:$J$206,$A17) -> 0 | E17: =SUMIFS(Investments!$V$7:$V$206,Investments!$J$7:$J$206,$A17) -> 0
A18: Traditional IRA | B18: =SUMIFS(Investments!$O$7:$O$206,Investments!$J$7:$J$206,$A18) -> 0 | C18: =SUMIFS(Investments!$P$7:$P$206,Investments!$J$7:$J$206,$A18) -> 0 | D18: =SUMIFS(Investments!$U$7:$U$206,Investments!$J$7:$J$206,$A18) -> 0 | E18: =SUMIFS(Investments!$V$7:$V$206,Investments!$J$7:$J$206,$A18) -> 0
A19: Roth IRA | B19: =SUMIFS(Investments!$O$7:$O$206,Investments!$J$7:$J$206,$A19) -> 0 | C19: =SUMIFS(Investments!$P$7:$P$206,Investments!$J$7:$J$206,$A19) -> 0 | D19: =SUMIFS(Investments!$U$7:$U$206,Investments!$J$7:$J$206,$A19) -> 0 | E19: =SUMIFS(Investments!$V$7:$V$206,Investments!$J$7:$J$206,$A19) -> 0
A20: SDIRA | B20: =SUMIFS(Investments!$O$7:$O$206,Investments!$J$7:$J$206,$A20) -> 0 | C20: =SUMIFS(Investments!$P$7:$P$206,Investments!$J$7:$J$206,$A20) -> 0 | D20: =SUMIFS(Investments!$U$7:$U$206,Investments!$J$7:$J$206,$A20) -> 0 | E20: =SUMIFS(Investments!$V$7:$V$206,Investments!$J$7:$J$206,$A20) -> 0
A21: Trust | B21: =SUMIFS(Investments!$O$7:$O$206,Investments!$J$7:$J$206,$A21) -> 0 | C21: =SUMIFS(Investments!$P$7:$P$206,Investments!$J$7:$J$206,$A21) -> 0 | D21: =SUMIFS(Investments!$U$7:$U$206,Investments!$J$7:$J$206,$A21) -> 0 | E21: =SUMIFS(Investments!$V$7:$V$206,Investments!$J$7:$J$206,$A21) -> 0
A22: Other | B22: =SUMIFS(Investments!$O$7:$O$206,Investments!$J$7:$J$206,$A22) -> 0 | C22: =SUMIFS(Investments!$P$7:$P$206,Investments!$J$7:$J$206,$A22) -> 0 | D22: =SUMIFS(Investments!$U$7:$U$206,Investments!$J$7:$J$206,$A22) -> 0 | E22: =SUMIFS(Investments!$V$7:$V$206,Investments!$J$7:$J$206,$A22) -> 0
A23: By Tax Bucket (est.)
A25: Tax Bucket | B25: Committed | C25: Funded | D25: Current Value | E25: Distributions
A26: Portfolio | B26: =SUMIFS(Investments!$O$7:$O$206,Investments!$L$7:$L$206,$A26) -> 330000 | C26: =SUMIFS(Investments!$P$7:$P$206,Investments!$L$7:$L$206,$A26) -> 130000 | D26: =SUMIFS(Investments!$U$7:$U$206,Investments!$L$7:$L$206,$A26) -> 130000 | E26: =SUMIFS(Investments!$V$7:$V$206,Investments!$L$7:$L$206,$A26) -> 0
A27: Passive | B27: =SUMIFS(Investments!$O$7:$O$206,Investments!$L$7:$L$206,$A27) -> 300000 | C27: =SUMIFS(Investments!$P$7:$P$206,Investments!$L$7:$L$206,$A27) -> 210000 | D27: =SUMIFS(Investments!$U$7:$U$206,Investments!$L$7:$L$206,$A27) -> 210000 | E27: =SUMIFS(Investments!$V$7:$V$206,Investments!$L$7:$L$206,$A27) -> 0
A28: Active | B28: =SUMIFS(Investments!$O$7:$O$206,Investments!$L$7:$L$206,$A28) -> 0 | C28: =SUMIFS(Investments!$P$7:$P$206,Investments!$L$7:$L$206,$A28) -> 0 | D28: =SUMIFS(Investments!$U$7:$U$206,Investments!$L$7:$L$206,$A28) -> 0 | E28: =SUMIFS(Investments!$V$7:$V$206,Investments!$L$7:$L$206,$A28) -> 0
A29: UBTI | B29: =SUMIFS(Investments!$O$7:$O$206,Investments!$L$7:$L$206,$A29) -> 0 | C29: =SUMIFS(Investments!$P$7:$P$206,Investments!$L$7:$L$206,$A29) -> 0 | D29: =SUMIFS(Investments!$U$7:$U$206,Investments!$L$7:$L$206,$A29) -> 0 | E29: =SUMIFS(Investments!$V$7:$V$206,Investments!$L$7:$L$206,$A29) -> 0
A30: Unknown | B30: =SUMIFS(Investments!$O$7:$O$206,Investments!$L$7:$L$206,$A30) -> 0 | C30: =SUMIFS(Investments!$P$7:$P$206,Investments!$L$7:$L$206,$A30) -> 0 | D30: =SUMIFS(Investments!$U$7:$U$206,Investments!$L$7:$L$206,$A30) -> 0 | E30: =SUMIFS(Investments!$V$7:$V$206,Investments!$L$7:$L$206,$A30) -> 0

Sheet Dashboard
B2: PRIVATE MARKETS | P2: =TEXT(TODAY(),"mmm d, yyyy") -> Apr 28, 2026
B3: Growth Circle · Portfolio Summary
B5: ACCOUNT FILTER | C5: ASSET CLASS FILTER
B6: All | C6: All
B8: TOTAL COMMITTED | D8: FUNDED | F8: UNFUNDED | H8: CURRENT VALUE | J8: DISTRIBUTIONS | L8: MOIC (WEIGHTED)
B10: =SUMIFS(Investments!$O$7:$O$206,Investments!$J$7:$J$206,IF($B$6="All","*",$B$6),Investments!$D$7:$D$206,IF($C$6="All","*",$C$6)) -> 630000 | D10: =SUMIFS(Investments!$P$7:$P$206,Investments!$J$7:$J$206,IF($B$6="All","*",$B$6),Investments!$D$7:$D$206,IF($C$6="All","*",$C$6)) -> 340000 | F10: =SUMIFS(Investments!$Q$7:$Q$206,Investments!$J$7:$J$206,IF($B$6="All","*",$B$6),Investments!$D$7:$D$206,IF($C$6="All","*",$C$6)) -> 290000 | H10: =SUMIFS(Investments!$U$7:$U$206,Investments!$J$7:$J$206,IF($B$6="All","*",$B$6),Investments!$D$7:$D$206,IF($C$6="All","*",$C$6)) -> 340000 | J10: =SUMIFS(Investments!$V$7:$V$206,Investments!$J$7:$J$206,IF($B$6="All","*",$B$6),Investments!$D$7:$D$206,IF($C$6="All","*",$C$6)) -> 0 | L10: =IFERROR(SUMPRODUCT(N(+Investments!$O$7:$O$206)*N(+Investments!$AA$7:$AA$206)*(N(+Investments!$AA$7:$AA$206)>0)*((Investments!$J$7:$J$206=$B$6)+($B$6="All"))*((Investments!$D$7:$D$206=$C$6)+($C$6="All")))/SUMPRODUCT(N(+Investments!$O$7:$O$206)*(N(+Investments!$AA$7:$AA$206)>0)*((Investments!$J$7:$J$206=$B$6)+($B$6="All"))*((Investments!$D$7:$D$206=$C$6)+($C$6="All"))),"") -> 3.6198413
B11: =IFERROR(COUNTIFS(Investments!$A$7:$A$206,"<>",Investments!$J$7:$J$206,IF($B$6="All","*",$B$6),Investments!$D$7:$D$206,IF($C$6="All","*",$C$6))&" deals","") -> 12 deals | D11: =IFERROR(TEXT($E$10/$C$10,"0%"),"—")&" of committed" -> — of committed | F11: ="future capital calls" -> future capital calls | H11: ="marked to last update" -> marked to last update | J11: ="lifetime cash returned" -> lifetime cash returned | L11: ="incl. distributions" -> incl. distributions
B13: ALLOCATION BY ASSET CLASS | J13: R-CODE COVERAGE
B14: ASSET CLASS | C14: COMMITTED | D14: FUNDED | E14: % OF FUNDED | F14: CURRENT VALUE | G14: MOIC | J14: R0 | K14: R1 | L14: R2 | M14: R3 | N14: R4
B15: VC | C15: =SUMIFS(Investments!$O$7:$O$206,Investments!$D$7:$D$206,"VC",Investments!$J$7:$J$206,IF($B$6="All","*",$B$6)) -> 330000 | D15: =SUMIFS(Investments!$P$7:$P$206,Investments!$D$7:$D$206,"VC",Investments!$J$7:$J$206,IF($B$6="All","*",$B$6)) -> 130000 | E15: =IFERROR(D15/$D$10,0) -> 0.38235294 | F15: =SUMIFS(Investments!$U$7:$U$206,Investments!$D$7:$D$206,"VC",Investments!$J$7:$J$206,IF($B$6="All","*",$B$6)) -> 130000 | G15: =IFERROR((F15+SUMIFS(Investments!$V$7:$V$206,Investments!$D$7:$D$206,"VC",Investments!$J$7:$J$206,IF($B$6="All","*",$B$6)))/D15,"") -> 1 | J15: =IFERROR(IF(COUNTIF(GC_Framework!$C$5:$C$204,"R0")=0,"—",COUNTIF(GC_Framework!$C$5:$C$204,"R0")),"—") -> — | K15: =IFERROR(IF(COUNTIF(GC_Framework!$C$5:$C$204,"R1")=0,"—",COUNTIF(GC_Framework!$C$5:$C$204,"R1")),"—") -> — | L15: =IFERROR(IF(COUNTIF(GC_Framework!$C$5:$C$204,"R2")=0,"—",COUNTIF(GC_Framework!$C$5:$C$204,"R2")),"—") -> 2 | M15: =IFERROR(IF(COUNTIF(GC_Framework!$C$5:$C$204,"R3")=0,"—",COUNTIF(GC_Framework!$C$5:$C$204,"R3")),"—") -> 1 | N15: =IFERROR(IF(COUNTIF(GC_Framework!$C$5:$C$204,"R4")=0,"—",COUNTIF(GC_Framework!$C$5:$C$204,"R4")),"—") -> 2
B16: Private Equity | C16: =SUMIFS(Investments!$O$7:$O$206,Investments!$D$7:$D$206,"Private Equity",Investments!$J$7:$J$206,IF($B$6="All","*",$B$6)) -> 100000 | D16: =SUMIFS(Investments!$P$7:$P$206,Investments!$D$7:$D$206,"Private Equity",Investments!$J$7:$J$206,IF($B$6="All","*",$B$6)) -> 100000 | E16: =IFERROR(D16/$D$10,0) -> 0.29411765 | F16: =SUMIFS(Investments!$U$7:$U$206,Investments!$D$7:$D$206,"Private Equity",Investments!$J$7:$J$206,IF($B$6="All","*",$B$6)) -> 100000 | G16: =IFERROR((F16+SUMIFS(Investments!$V$7:$V$206,Investments!$D$7:$D$206,"Private Equity",Investments!$J$7:$J$206,IF($B$6="All","*",$B$6)))/D16,"") -> 1 | J16: Cash / Optionality | K16: Public Beta | L16: Anchor Income | M16: High-Yield Private | N16: Value-Add PE
B17: Real Estate | C17: =SUMIFS(Investments!$O$7:$O$206,Investments!$D$7:$D$206,"Real Estate",Investments!$J$7:$J$206,IF($B$6="All","*",$B$6)) -> 100000 | D17: =SUMIFS(Investments!$P$7:$P$206,Investments!$D$7:$D$206,"Real Estate",Investments!$J$7:$J$206,IF($B$6="All","*",$B$6)) -> 100000 | E17: =IFERROR(D17/$D$10,0) -> 0.29411765 | F17: =SUMIFS(Investments!$U$7:$U$206,Investments!$D$7:$D$206,"Real Estate",Investments!$J$7:$J$206,IF($B$6="All","*",$B$6)) -> 100000 | G17: =IFERROR((F17+SUMIFS(Investments!$V$7:$V$206,Investments!$D$7:$D$206,"Real Estate",Investments!$J$7:$J$206,IF($B$6="All","*",$B$6)))/D17,"") -> 1
B18: Private Credit | C18: =SUMIFS(Investments!$O$7:$O$206,Investments!$D$7:$D$206,"Private Credit",Investments!$J$7:$J$206,IF($B$6="All","*",$B$6)) -> 100000 | D18: =SUMIFS(Investments!$P$7:$P$206,Investments!$D$7:$D$206,"Private Credit",Investments!$J$7:$J$206,IF($B$6="All","*",$B$6)) -> 10000 | E18: =IFERROR(D18/$D$10,0) -> 0.029411765 | F18: =SUMIFS(Investments!$U$7:$U$206,Investments!$D$7:$D$206,"Private Credit",Investments!$J$7:$J$206,IF($B$6="All","*",$B$6)) -> 10000 | G18: =IFERROR((F18+SUMIFS(Investments!$V$7:$V$206,Investments!$D$7:$D$206,"Private Credit",Investments!$J$7:$J$206,IF($B$6="All","*",$B$6)))/D18,"") -> 1 | J18: R5 | K18: R6 | L18: R7 | M18: R8 | N18: R9
B19: Other | C19: =SUMIFS(Investments!$O$7:$O$206,Investments!$D$7:$D$206,"Other",Investments!$J$7:$J$206,IF($B$6="All","*",$B$6)) -> 0 | D19: =SUMIFS(Investments!$P$7:$P$206,Investments!$D$7:$D$206,"Other",Investments!$J$7:$J$206,IF($B$6="All","*",$B$6)) -> 0 | E19: =IFERROR(D19/$D$10,0) -> 0 | F19: =SUMIFS(Investments!$U$7:$U$206,Investments!$D$7:$D$206,"Other",Investments!$J$7:$J$206,IF($B$6="All","*",$B$6)) -> 0 | G19: =IFERROR((F19+SUMIFS(Investments!$V$7:$V$206,Investments!$D$7:$D$206,"Other",Investments!$J$7:$J$206,IF($B$6="All","*",$B$6)))/D19,"") | J19: =IFERROR(IF(COUNTIF(GC_Framework!$C$5:$C$204,"R5")=0,"—",COUNTIF(GC_Framework!$C$5:$C$204,"R5")),"—") -> — | K19: =IFERROR(IF(COUNTIF(GC_Framework!$C$5:$C$204,"R6")=0,"—",COUNTIF(GC_Framework!$C$5:$C$204,"R6")),"—") -> 2 | L19: =IFERROR(IF(COUNTIF(GC_Framework!$C$5:$C$204,"R7")=0,"—",COUNTIF(GC_Framework!$C$5:$C$204,"R7")),"—") -> 3 | M19: =IFERROR(IF(COUNTIF(GC_Framework!$C$5:$C$204,"R8")=0,"—",COUNTIF(GC_Framework!$C$5:$C$204,"R8")),"—") -> 2 | N19: =IFERROR(IF(COUNTIF(GC_Framework!$C$5:$C$204,"R9")=0,"—",COUNTIF(GC_Framework!$C$5:$C$204,"R9")),"—") -> —
B20: TOTAL | C20: =SUM(C15:C19) -> 630000 | D20: =SUM(D15:D19) -> 340000 | E20: =SUM(E15:E19) -> 1 | F20: =SUM(F15:F19) -> 340000 | G20: =IFERROR(SUMPRODUCT(N(+Investments!$O$7:$O$206)*N(+Investments!$AA$7:$AA$206)*(N(+Investments!$AA$7:$AA$206)>0)*((Investments!$J$7:$J$206=$B$6)+($B$6="All"))*((Investments!$D$7:$D$206=$C$6)+($C$6="All")))/SUMPRODUCT(N(+Investments!$O$7:$O$206)*(N(+Investments!$AA$7:$AA$206)>0)*((Investments!$J$7:$J$206=$B$6)+($B$6="All"))*((Investments!$D$7:$D$206=$C$6)+($C$6="All"))),"") -> 3.6198413 | J20: Special Situations | K20: Franchise / Brand IP | L20: Platform VC | M20: Moonshot / Binary | N20: Diversifier
B38: DEAL DETAIL — INVESTMENTS × GC FRAMEWORK
B39: DEAL ID | C39: DEAL NAME | D39: ASSET CLASS | E39: ACCOUNT | F39: STATUS | G39: COMMIT | H39: FUNDED | I39: UNFUND | J39: CURRENT | K39: DIST | L39: MOIC | M39: GC SCORE | N39: R-CODE | O39: TIER | P39: VERDICT
B40: =IFERROR(IF(Investments!A7="","",Investments!A7),"") -> GC-RE-001 | C40: =IFERROR(IF(Investments!B7="","",Investments!B7),"") -> Eephus Growth Fund I | D40: =IFERROR(IF(Investments!A7="","",Investments!D7),"") -> Real Estate | E40: =IFERROR(IF(Investments!J7="","",Investments!J7),"") -> SD-IRA | F40: =IFERROR(IF(Investments!A7="","",Investments!G7),"") -> Closed | G40: =IFERROR(IF(Investments!O7="","",Investments!O7),"") -> 50000 | H40: =IFERROR(IF(Investments!P7="","",Investments!P7),"") -> 50000 | I40: =IFERROR(IF(Investments!Q7="","",Investments!Q7),"") -> 0 | J40: =IFERROR(IF(Investments!U7="","",Investments!U7),"") -> 50000 | K40: =IFERROR(IF(Investments!V7="","",Investments!V7),"") -> 0 | L40: =IFERROR(IF(Investments!AB7="","",Investments!AB7),"") -> 1 | M40: =IFERROR(IF(Investments!A7="","",IFERROR(VLOOKUP(Investments!A7,GC_Framework!$A$5:$P$204,2,FALSE()),"")),"") -> 0 | N40: =IFERROR(IF(Investments!A7="","",IFERROR(VLOOKUP(Investments!A7,GC_Framework!$A$5:$P$204,3,FALSE()),"")),"") -> R2 | O40: =IFERROR(IF(Investments!A7="","",IFERROR(VLOOKUP(Investments!A7,GC_Framework!$A$5:$P$204,5,FALSE()),"")),"") -> Core | P40: =IFERROR(IF(Investments!A7="","",IFERROR(VLOOKUP(Investments!A7,GC_Framework!$A$5:$P$204,9,FALSE()),"")),"") -> Yes — strong cash flow + tax
B41: =IFERROR(IF(Investments!A8="","",Investments!A8),"") -> GC-PE-001 | C41: =IFERROR(IF(Investments!B8="","",Investments!B8),"") -> BlueBird Capital (Tranche 1) | D41: =IFERROR(IF(Investments!A8="","",Investments!D8),"") -> Private Equity | E41: =IFERROR(IF(Investments!J8="","",Investments!J8),"") -> SD-IRA | F41: =IFERROR(IF(Investments!A8="","",Investments!G8),"") -> Closed | G41: =IFERROR(IF(Investments!O8="","",Investments!O8),"") -> 50000 | H41: =IFERROR(IF(Investments!P8="","",Investments!P8),"") -> 50000 | I41: =IFERROR(IF(Investments!Q8="","",Investments!Q8),"") -> 0 | J41: =IFERROR(IF(Investments!U8="","",Investments!U8),"") -> 50000 | K41: =IFERROR(IF(Investments!V8="","",Investments!V8),"") -> 0 | L41: =IFERROR(IF(Investments!AB8="","",Investments!AB8),"") -> 1 | M41: =IFERROR(IF(Investments!A8="","",IFERROR(VLOOKUP(Investments!A8,GC_Framework!$A$5:$P$204,2,FALSE()),"")),"") -> 0 | N41: =IFERROR(IF(Investments!A8="","",IFERROR(VLOOKUP(Investments!A8,GC_Framework!$A$5:$P$204,3,FALSE()),"")),"") -> R4 | O41: =IFERROR(IF(Investments!A8="","",IFERROR(VLOOKUP(Investments!A8,GC_Framework!$A$5:$P$204,5,FALSE()),"")),"") -> Core | P41: =IFERROR(IF(Investments!A8="","",IFERROR(VLOOKUP(Investments!A8,GC_Framework!$A$5:$P$204,9,FALSE()),"")),"") -> Yes — strong distribution yield
B42: =IFERROR(IF(Investments!A9="","",Investments!A9),"") -> GC-VC-001 | C42: =IFERROR(IF(Investments!B9="","",Investments!B9),"") -> Next Life Sciences - Plan A | D42: =IFERROR(IF(Investments!A9="","",Investments!D9),"") -> VC | E42: =IFERROR(IF(Investments!J9="","",Investments!J9),"") -> SD-IRA | F42: =IFERROR(IF(Investments!A9="","",Investments!G9),"") -> Closed | G42: =IFERROR(IF(Investments!O9="","",Investments!O9),"") -> 10000 | H42: =IFERROR(IF(Investments!P9="","",Investments!P9),"") -> 10000 | I42: =IFERROR(IF(Investments!Q9="","",Investments!Q9),"") -> 0 | J42: =IFERROR(IF(Investments!U9="","",Investments!U9),"") -> 10000 | K42: =IFERROR(IF(Investments!V9="","",Investments!V9),"") -> 0 | L42: =IFERROR(IF(Investments!AB9="","",Investments!AB9),"") -> 1 | M42: =IFERROR(IF(Investments!A9="","",IFERROR(VLOOKUP(Investments!A9,GC_Framework!$A$5:$P$204,2,FALSE()),"")),"") -> 0 | N42: =IFERROR(IF(Investments!A9="","",IFERROR(VLOOKUP(Investments!A9,GC_Framework!$A$5:$P$204,3,FALSE()),"")),"") -> R8 | O42: =IFERROR(IF(Investments!A9="","",IFERROR(VLOOKUP(Investments!A9,GC_Framework!$A$5:$P$204,5,FALSE()),"")),"") -> Opportunistic | P42: =IFERROR(IF(Investments!A9="","",IFERROR(VLOOKUP(Investments!A9,GC_Framework!$A$5:$P$204,9,FALSE()),"")),"") -> Yes — asymmetric upside
B43: =IFERROR(IF(Investments!A10="","",Investments!A10),"") -> GC-VC-002 | C43: =IFERROR(IF(Investments!B10="","",Investments!B10),"") -> Telly TV | D43: =IFERROR(IF(Investments!A10="","",Investments!D10),"") -> VC | E43: =IFERROR(IF(Investments!J10="","",Investments!J10),"") -> SD-IRA | F43: =IFERROR(IF(Investments!A10="","",Investments!G10),"") -> Closed | G43: =IFERROR(IF(Investments!O10="","",Investments!O10),"") -> 5000 | H43: =IFERROR(IF(Investments!P10="","",Investments!P10),"") -> 5000 | I43: =IFERROR(IF(Investments!Q10="","",Investments!Q10),"") -> 0 | J43: =IFERROR(IF(Investments!U10="","",Investments!U10),"") -> 5000 | K43: =IFERROR(IF(Investments!V10="","",Investments!V10),"") -> 0 | L43: =IFERROR(IF(Investments!AB10="","",Investments!AB10),"") -> 1 | M43: =IFERROR(IF(Investments!A10="","",IFERROR(VLOOKUP(Investments!A10,GC_Framework!$A$5:$P$204,2,FALSE()),"")),"") -> 78 | N43: =IFERROR(IF(Investments!A10="","",IFERROR(VLOOKUP(Investments!A10,GC_Framework!$A$5:$P$204,3,FALSE()),"")),"") -> R7 | O43: =IFERROR(IF(Investments!A10="","",IFERROR(VLOOKUP(Investments!A10,GC_Framework!$A$5:$P$204,5,FALSE()),"")),"") -> Opportunistic | P43: =IFERROR(IF(Investments!A10="","",IFERROR(VLOOKUP(Investments!A10,GC_Framework!$A$5:$P$204,9,FALSE()),"")),"") -> Borderline — small position
B44: =IFERROR(IF(Investments!A11="","",Investments!A11),"") -> GC-VC-003 | C44: =IFERROR(IF(Investments!B11="","",Investments!B11),"") -> ÆRTHLINGS | D44: =IFERROR(IF(Investments!A11="","",Investments!D11),"") -> VC | E44: =IFERROR(IF(Investments!J11="","",Investments!J11),"") -> SD-IRA | F44: =IFERROR(IF(Investments!A11="","",Investments!G11),"") -> Closed | G44: =IFERROR(IF(Investments!O11="","",Investments!O11),"") -> 10000 | H44: =IFERROR(IF(Investments!P11="","",Investments!P11),"") -> 10000 | I44: =IFERROR(IF(Investments!Q11="","",Investments!Q11),"") -> 0 | J44: =IFERROR(IF(Investments!U11="","",Investments!U11),"") -> 10000 | K44: =IFERROR(IF(Investments!V11="","",Investments!V11),"") -> 0 | L44: =IFERROR(IF(Investments!AB11="","",Investments!AB11),"") -> 1 | M44: =IFERROR(IF(Investments!A11="","",IFERROR(VLOOKUP(Investments!A11,GC_Framework!$A$5:$P$204,2,FALSE()),"")),"") -> 88 | N44: =IFERROR(IF(Investments!A11="","",IFERROR(VLOOKUP(Investments!A11,GC_Framework!$A$5:$P$204,3,FALSE()),"")),"") -> R6 | O44: =IFERROR(IF(Investments!A11="","",IFERROR(VLOOKUP(Investments!A11,GC_Framework!$A$5:$P$204,5,FALSE()),"")),"") -> Opportunistic | P44: =IFERROR(IF(Investments!A11="","",IFERROR(VLOOKUP(Investments!A11,GC_Framework!$A$5:$P$204,9,FALSE()),"")),"") -> Yes — category IP optionality
B45: =IFERROR(IF(Investments!A12="","",Investments!A12),"") -> GC-VC-004 | C45: =IFERROR(IF(Investments!B12="","",Investments!B12),"") -> SpaceStation Fund | D45: =IFERROR(IF(Investments!A12="","",Investments!D12),"") -> VC | E45: =IFERROR(IF(Investments!J12="","",Investments!J12),"") -> SD-IRA | F45: =IFERROR(IF(Investments!A12="","",Investments!G12),"") -> Opened | G45: =IFERROR(IF(Investments!O12="","",Investments!O12),"") -> 250000 | H45: =IFERROR(IF(Investments!P12="","",Investments!P12),"") -> 50000 | I45: =IFERROR(IF(Investments!Q12="","",Investments!Q12),"") -> 200000 | J45: =IFERROR(IF(Investments!U12="","",Investments!U12),"") -> 50000 | K45: =IFERROR(IF(Investments!V12="","",Investments!V12),"") -> 0 | L45: =IFERROR(IF(Investments!AB12="","",Investments!AB12),"") -> 1 | M45: =IFERROR(IF(Investments!A12="","",IFERROR(VLOOKUP(Investments!A12,GC_Framework!$A$5:$P$204,2,FALSE()),"")),"") -> 0 | N45: =IFERROR(IF(Investments!A12="","",IFERROR(VLOOKUP(Investments!A12,GC_Framework!$A$5:$P$204,3,FALSE()),"")),"") -> R7 | O45: =IFERROR(IF(Investments!A12="","",IFERROR(VLOOKUP(Investments!A12,GC_Framework!$A$5:$P$204,5,FALSE()),"")),"") -> Core | P45: =IFERROR(IF(Investments!A12="","",IFERROR(VLOOKUP(Investments!A12,GC_Framework!$A$5:$P$204,9,FALSE()),"")),"") -> Yes — diversified fund exposure
B46: =IFERROR(IF(Investments!A13="","",Investments!A13),"") -> GC-VC-005 | C46: =IFERROR(IF(Investments!B13="","",Investments!B13),"") -> Turbo Insurance | D46: =IFERROR(IF(Investments!A13="","",Investments!D13),"") -> VC | E46: =IFERROR(IF(Investments!J13="","",Investments!J13),"") -> SD-IRA | F46: =IFERROR(IF(Investments!A13="","",Investments!G13),"") -> Closed | G46: =IFERROR(IF(Investments!O13="","",Investments!O13),"") -> 20000 | H46: =IFERROR(IF(Investments!P13="","",Investments!P13),"") -> 20000 | I46: =IFERROR(IF(Investments!Q13="","",Investments!Q13),"") -> 0 | J46: =IFERROR(IF(Investments!U13="","",Investments!U13),"") -> 20000 | K46: =IFERROR(IF(Investments!V13="","",Investments!V13),"") -> 0 | L46: =IFERROR(IF(Investments!AB13="","",Investments!AB13),"") -> 1 | M46: =IFERROR(IF(Investments!A13="","",IFERROR(VLOOKUP(Investments!A13,GC_Framework!$A$5:$P$204,2,FALSE()),"")),"") -> 0 | N46: =IFERROR(IF(Investments!A13="","",IFERROR(VLOOKUP(Investments!A13,GC_Framework!$A$5:$P$204,3,FALSE()),"")),"") -> R7 | O46: =IFERROR(IF(Investments!A13="","",IFERROR(VLOOKUP(Investments!A13,GC_Framework!$A$5:$P$204,5,FALSE()),"")),"") -> Opportunistic | P46: =IFERROR(IF(Investments!A13="","",IFERROR(VLOOKUP(Investments!A13,GC_Framework!$A$5:$P$204,9,FALSE()),"")),"") -> Yes — AI x insurance thesis
B47: =IFERROR(IF(Investments!A14="","",Investments!A14),"") -> GC-RE-002 | C47: =IFERROR(IF(Investments!B14="","",Investments!B14),"") -> Eephus Growth Fund II | D47: =IFERROR(IF(Investments!A14="","",Investments!D14),"") -> Real Estate | E47: =IFERROR(IF(Investments!J14="","",Investments!J14),"") -> SD-IRA | F47: =IFERROR(IF(Investments!A14="","",Investments!G14),"") -> Opened | G47: =IFERROR(IF(Investments!O14="","",Investments!O14),"") -> 50000 | H47: =IFERROR(IF(Investments!P14="","",Investments!P14),"") -> 50000 | I47: =IFERROR(IF(Investments!Q14="","",Investments!Q14),"") -> 0 | J47: =IFERROR(IF(Investments!U14="","",Investments!U14),"") -> 50000 | K47: =IFERROR(IF(Investments!V14="","",Investments!V14),"") -> 0 | L47: =IFERROR(IF(Investments!AB14="","",Investments!AB14),"") -> 1 | M47: =IFERROR(IF(Investments!A14="","",IFERROR(VLOOKUP(Investments!A14,GC_Framework!$A$5:$P$204,2,FALSE()),"")),"") -> 0 | N47: =IFERROR(IF(Investments!A14="","",IFERROR(VLOOKUP(Investments!A14,GC_Framework!$A$5:$P$204,3,FALSE()),"")),"") -> R2 | O47: =IFERROR(IF(Investments!A14="","",IFERROR(VLOOKUP(Investments!A14,GC_Framework!$A$5:$P$204,5,FALSE()),"")),"") -> Core | P47: =IFERROR(IF(Investments!A14="","",IFERROR(VLOOKUP(Investments!A14,GC_Framework!$A$5:$P$204,9,FALSE()),"")),"") -> Yes — recurring preferred income
B48: =IFERROR(IF(Investments!A15="","",Investments!A15),"") -> GC-PE-002 | C48: =IFERROR(IF(Investments!B15="","",Investments!B15),"") -> BlueBird Capital (Tranche 2) | D48: =IFERROR(IF(Investments!A15="","",Investments!D15),"") -> Private Equity | E48: =IFERROR(IF(Investments!J15="","",Investments!J15),"") -> SD-IRA | F48: =IFERROR(IF(Investments!A15="","",Investments!G15),"") -> Closed | G48: =IFERROR(IF(Investments!O15="","",Investments!O15),"") -> 50000 | H48: =IFERROR(IF(Investments!P15="","",Investments!P15),"") -> 50000 | I48: =IFERROR(IF(Investments!Q15="","",Investments!Q15),"") -> 0 | J48: =IFERROR(IF(Investments!U15="","",Investments!U15),"") -> 50000 | K48: =IFERROR(IF(Investments!V15="","",Investments!V15),"") -> 0 | L48: =IFERROR(IF(Investments!AB15="","",Investments!AB15),"") -> 1 | M48: =IFERROR(IF(Investments!A15="","",IFERROR(VLOOKUP(Investments!A15,GC_Framework!$A$5:$P$204,2,FALSE()),"")),"") -> 0 | N48: =IFERROR(IF(Investments!A15="","",IFERROR(VLOOKUP(Investments!A15,GC_Framework!$A$5:$P$204,3,FALSE()),"")),"") -> R4 | O48: =IFERROR(IF(Investments!A15="","",IFERROR(VLOOKUP(Investments!A15,GC_Framework!$A$5:$P$204,5,FALSE()),"")),"") -> Core | P48: =IFERROR(IF(Investments!A15="","",IFERROR(VLOOKUP(Investments!A15,GC_Framework!$A$5:$P$204,9,FALSE()),"")),"") -> Yes — strong distribution yield
B49: =IFERROR(IF(Investments!A16="","",Investments!A16),"") -> GC-VC-006 | C49: =IFERROR(IF(Investments!B16="","",Investments!B16),"") -> Aerolane | D49: =IFERROR(IF(Investments!A16="","",Investments!D16),"") -> VC | E49: =IFERROR(IF(Investments!J16="","",Investments!J16),"") -> SD-IRA | F49: =IFERROR(IF(Investments!A16="","",Investments!G16),"") -> Closed | G49: =IFERROR(IF(Investments!O16="","",Investments!O16),"") -> 25000 | H49: =IFERROR(IF(Investments!P16="","",Investments!P16),"") -> 25000 | I49: =IFERROR(IF(Investments!Q16="","",Investments!Q16),"") -> 0 | J49: =IFERROR(IF(Investments!U16="","",Investments!U16),"") -> 25000 | K49: =IFERROR(IF(Investments!V16="","",Investments!V16),"") -> 0 | L49: =IFERROR(IF(Investments!AB16="","",Investments!AB16),"") -> 1 | M49: =IFERROR(IF(Investments!A16="","",IFERROR(VLOOKUP(Investments!A16,GC_Framework!$A$5:$P$204,2,FALSE()),"")),"") -> 90 | N49: =IFERROR(IF(Investments!A16="","",IFERROR(VLOOKUP(Investments!A16,GC_Framework!$A$5:$P$204,3,FALSE()),"")),"") -> R8 | O49: =IFERROR(IF(Investments!A16="","",IFERROR(VLOOKUP(Investments!A16,GC_Framework!$A$5:$P$204,5,FALSE()),"")),"") -> Opportunistic | P49: =IFERROR(IF(Investments!A16="","",IFERROR(VLOOKUP(Investments!A16,GC_Framework!$A$5:$P$204,9,FALSE()),"")),"") -> Yes — infrastructure optionality
B50: =IFERROR(IF(Investments!A17="","",Investments!A17),"") -> GC-VC-007 | C50: =IFERROR(IF(Investments!B17="","",Investments!B17),"") -> Rorra | D50: =IFERROR(IF(Investments!A17="","",Investments!D17),"") -> VC | E50: =IFERROR(IF(Investments!J17="","",Investments!J17),"") -> SD-IRA | F50: =IFERROR(IF(Investments!A17="","",Investments!G17),"") -> Closed | G50: =IFERROR(IF(Investments!O17="","",Investments!O17),"") -> 10000 | H50: =IFERROR(IF(Investments!P17="","",Investments!P17),"") -> 10000 | I50: =IFERROR(IF(Investments!Q17="","",Investments!Q17),"") -> 0 | J50: =IFERROR(IF(Investments!U17="","",Investments!U17),"") -> 10000 | K50: =IFERROR(IF(Investments!V17="","",Investments!V17),"") -> 0 | L50: =IFERROR(IF(Investments!AB17="","",Investments!AB17),"") -> 1 | M50: =IFERROR(IF(Investments!A17="","",IFERROR(VLOOKUP(Investments!A17,GC_Framework!$A$5:$P$204,2,FALSE()),"")),"") -> 0 | N50: =IFERROR(IF(Investments!A17="","",IFERROR(VLOOKUP(Investments!A17,GC_Framework!$A$5:$P$204,3,FALSE()),"")),"") -> R6 | O50: =IFERROR(IF(Investments!A17="","",IFERROR(VLOOKUP(Investments!A17,GC_Framework!$A$5:$P$204,5,FALSE()),"")),"") -> Opportunistic | P50: =IFERROR(IF(Investments!A17="","",IFERROR(VLOOKUP(Investments!A17,GC_Framework!$A$5:$P$204,9,FALSE()),"")),"") -> Yes — strong subscription model
B51: =IFERROR(IF(Investments!A18="","",Investments!A18),"") -> GC-PE-003 | C51: =IFERROR(IF(Investments!B18="","",Investments!B18),"") -> Asilia GC Fund | D51: =IFERROR(IF(Investments!A18="","",Investments!D18),"") -> Private Credit | E51: =IFERROR(IF(Investments!J18="","",Investments!J18),"") -> SD-IRA | F51: =IFERROR(IF(Investments!A18="","",Investments!G18),"") -> Opened | G51: =IFERROR(IF(Investments!O18="","",Investments!O18),"") -> 100000 | H51: =IFERROR(IF(Investments!P18="","",Investments!P18),"") -> 10000 | I51: =IFERROR(IF(Investments!Q18="","",Investments!Q18),"") -> 90000 | J51: =IFERROR(IF(Investments!U18="","",Investments!U18),"") -> 10000 | K51: =IFERROR(IF(Investments!V18="","",Investments!V18),"") -> 0 | L51: =IFERROR(IF(Investments!AB18="","",Investments!AB18),"") -> 1 | M51: =IFERROR(IF(Investments!A18="","",IFERROR(VLOOKUP(Investments!A18,GC_Framework!$A$5:$P$204,2,FALSE()),"")),"") -> 83 | N51: =IFERROR(IF(Investments!A18="","",IFERROR(VLOOKUP(Investments!A18,GC_Framework!$A$5:$P$204,3,FALSE()),"")),"") -> R3 | O51: =IFERROR(IF(Investments!A18="","",IFERROR(VLOOKUP(Investments!A18,GC_Framework!$A$5:$P$204,5,FALSE()),"")),"") -> Core | P51: =IFERROR(IF(Investments!A18="","",IFERROR(VLOOKUP(Investments!A18,GC_Framework!$A$5:$P$204,9,FALSE()),"")),"") -> Yes — strong yield + diversification
... B99: =IFERROR(IF(Investments!A66="","",Investments!A66),"") | C99: =IFERROR(IF(Investments!B66="","",Investments!B66),"") | D99: =IFERROR(IF(Investments!A66="","",Investments!D66),"") | E99: =IFERROR(IF(Investments!J66="","",Investments!J66),"") | F99: =IFERROR(IF(Investments!A66="","",Investments!G66),"") | G99: =IFERROR(IF(Investments!O66="","",Investments!O66),"") | H99: =IFERROR(IF(Investments!P66="","",Investments!P66),"") | I99: =IFERROR(IF(Investments!Q66="","",Investments!Q66),"") | J99: =IFERROR(IF(Investments!U66="","",Investments!U66),"") | K99: =IFERROR(IF(Investments!V66="","",Investments!V66),"") | L99: =IFERROR(IF(Investments!AB66="","",Investments!AB66),"") | M99: =IFERROR(IF(Investments!A66="","",IFERROR(VLOOKUP(Investments!A66,GC_Framework!$A$5:$P$204,2,FALSE()),"")),"") | N99: =IFERROR(IF(Investments!A66="","",IFERROR(VLOOKUP(Investments!A66,GC_Framework!$A$5:$P$204,3,FALSE()),"")),"") | O99: =IFERROR(IF(Investments!A66="","",IFERROR(VLOOKUP(Investments!A66,GC_Framework!$A$5:$P$204,5,FALSE()),"")),"") | P99: =IFERROR(IF(Investments!A66="","",IFERROR(VLOOKUP(Investments!A66,GC_Framework!$A$5:$P$204,9,FALSE()),"")),"")
B102: APEX · Private Markets Dashboard — reads Investments + GC_Framework · Filters above drive all KPIs and tables

Sheet Lists
A1: ListName | B1: Value
A2: AssetClass | B2: VC
A3: AssetClass | B3: Private Equity
A4: AssetClass | B4: Real Estate
A5: AssetClass | B5: Private Credit
A6: AssetClass | B6: Other
A7: VehicleType | B7: Fund
A8: VehicleType | B8: SPV
A9: VehicleType | B9: Syndicate
A10: VehicleType | B10: Direct
A11: VehicleType | B11: Other
A12: AccountType | B12: Taxable
... A37: YesNo | B37: No
A38: RCode | B38: R0 | C38: Reserve / Optionality
A39: RCode | B39: R1 | C39: Public Liquid Engine
A40: RCode | B40: R2 | C40: Anchor Income + Tax Shield
A41: RCode | B41: R3 | C41: Stabilized Real Estate
A42: RCode | B42: R4 | C42: Operational Value-Add PE
A43: RCode | B43: R5 | C43: Distressed / Special Situations
A44: RCode | B44: R6 | C44: Growth Equity
A45: RCode | B45: R7 | C45: Early-Stage VC
A46: RCode | B46: R8 | C46: Asymmetric Moonshot
A47: RCode | B47: R9 | C47: Other / Uncategorized
A48: Conviction | B48: Core
A49: Conviction | B49: Strategic
A50: Conviction | B50: Tactical
A51: Conviction | B51: Opportunistic
A52: Conviction | B52: Speculative
A53: Confidence | B53: High
A54: Confidence | B54: Medium
A55: Confidence | B55: Low

Sheet GC_Framework
A1: GC Framework — Qualitative Fields
A2: Qualitative fields from the GC Deal Comparison & Asset Allocation Framework. Keyed by Deal ID. Dashboard reads via VLOOKUP.
A3: Each row is one deal's qualitative scoring. The Deal ID in column A must EXACTLY match the Deal ID on the Investments sheet — that's how the dashboard links them. All cells here are yellow (user input).
A4: Deal ID | B4: GC Score (0-100) | C4: R-Code | D4: R-Code Label | E4: Conviction Tier | F4: Confidence | G4: Portfolio Role | H4: Killer Risk | I4: Regret Resistant | J4: Sizing Low ($) | K4: Sizing High ($) | L4: Sizing Recommended ($) | M4: Next Call Date | N4: Next Call Amount ($) | O4: Memo Iteration | P4: Memo Date
A5: GC-RE-001 | C5: R2 | D5: Anchor Income + Tax Shield | E5: Core | F5: High | G5: Income / Tax Shield | H5: Illiquidity / RE cycle risk | I5: Yes — strong cash flow + tax
A6: GC-PE-001 | C6: R4 | D6: Operational Value-Add PE | E6: Core | F6: High | G6: Cash-Flowing PE | H6: Manager execution / deal quality | I6: Yes — strong distribution yield
A7: GC-VC-001 | C7: R8 | D7: Asymmetric Moonshot | E7: Opportunistic | F7: Medium | G7: Binary Catalyst | H7: Clinical/regulatory failure | I7: Yes — asymmetric upside
A8: GC-VC-002 | B8: 78 | C8: R7 | D8: Platform-Scale VC | E8: Opportunistic | F8: Low | G8: High Beta VC | H8: Consumer hardware adoption risk | I8: Borderline — small position
A9: GC-VC-003 | B9: 88 | C9: R6 | D9: Franchise / Category IP | E9: Opportunistic | F9: Medium | G9: Brand / IP Upside | H9: Brand adoption / execution | I9: Yes — category IP optionality
A10: GC-VC-004 | C10: R7 | D10: Platform-Scale VC | E10: Core | F10: High | G10: High Beta Fund VC | H10: Capital call velocity / illiquidity | I10: Yes — diversified fund exposure
A11: GC-VC-005 | C11: R7 | D11: Platform-Scale VC | E11: Opportunistic | F11: Medium | G11: AI x Insurtech | H11: Early-stage execution / AI hype | I11: Yes — AI x insurance thesis
A12: GC-RE-002 | C12: R2 | D12: Anchor Income + Tax Shield | E12: Core | F12: High | G12: Income / Tax Shield | H12: RE cycle / rate risk | I12: Yes — recurring preferred income
A13: GC-PE-002 | C13: R4 | D13: Operational Value-Add PE | E13: Core | F13: High | G13: Cash-Flowing PE | H13: Manager execution / deal quality | I13: Yes — strong distribution yield
A14: GC-VC-006 | B14: 90 | C14: R8 | D14: Asymmetric Moonshot | E14: Opportunistic | F14: High | G14: Aerospace / Logistics | H14: Regulatory / capital intensity | I14: Yes — infrastructure optionality
A15: GC-VC-007 | C15: R6 | D15: Franchise / Category IP | E15: Opportunistic | F15: Medium | G15: Consumer Brand | H15: Early-stage brand execution | I15: Yes — strong subscription model
A16: GC-PE-003 | B16: 83 | C16: R3 | D16: High-Yield Private Credit | E16: Core | F16: High | G16: Private Credit | H16: Credit default / fund liquidity | I16: Yes — strong yield + diversification

Sheet CashFlow_Chart
A1: SD-IRA PRIVATE MARKETS — CASH FLOW ANALYSIS
A2: Capital Calls & Contributions (outflows) vs. Preferred Distributions (inflows) · Growth Circle Portfolio
A5: Quarter | B5: Contributions ($) | C5: Capital Calls ($) | D5: Distributions ($) | E5: Net Cash Flow ($) | F5: Cumulative Net ($)
A6: Q3 2025 | B6: =SUMIFS(CashFlows!$E$6:$E$309,CashFlows!$A$6:$A$309,">="&DATE(VALUE(MID($A6,4,4)),(VALUE(MID($A6,2,1))-1)*3+1,1),CashFlows!$A$6:$A$309,"<="&DATE(VALUE(MID($A6,4,4)),VALUE(MID($A6,2,1))*3+1,0),CashFlows!$G$6:$G$309,"Initial") -> -160000 | C6: =SUMIFS(CashFlows!$E$6:$E$309,CashFlows!$A$6:$A$309,">="&DATE(VALUE(MID($A6,4,4)),(VALUE(MID($A6,2,1))-1)*3+1,1),CashFlows!$A$6:$A$309,"<="&DATE(VALUE(MID($A6,4,4)),VALUE(MID($A6,2,1))*3+1,0),CashFlows!$G$6:$G$309,"Ongoing") -> 0 | D6: =SUMIFS(CashFlows!$E$6:$E$309,CashFlows!$A$6:$A$309,">="&DATE(VALUE(MID($A6,4,4)),(VALUE(MID($A6,2,1))-1)*3+1,1),CashFlows!$A$6:$A$309,"<="&DATE(VALUE(MID($A6,4,4)),VALUE(MID($A6,2,1))*3+1,0),CashFlows!$D$6:$D$309,"<>Capital Call",CashFlows!$D$6:$D$309,"<>") -> 0 | E6: =B6+C6+D6 -> -160000 | F6: =E6 -> -160000
A7: Q4 2025 | B7: =SUMIFS(CashFlows!$E$6:$E$309,CashFlows!$A$6:$A$309,">="&DATE(VALUE(MID($A7,4,4)),(VALUE(MID($A7,2,1))-1)*3+1,1),CashFlows!$A$6:$A$309,"<="&DATE(VALUE(MID($A7,4,4)),VALUE(MID($A7,2,1))*3+1,0),CashFlows!$G$6:$G$309,"Initial") -> -15000 | C7: =SUMIFS(CashFlows!$E$6:$E$309,CashFlows!$A$6:$A$309,">="&DATE(VALUE(MID($A7,4,4)),(VALUE(MID($A7,2,1))-1)*3+1,1),CashFlows!$A$6:$A$309,"<="&DATE(VALUE(MID($A7,4,4)),VALUE(MID($A7,2,1))*3+1,0),CashFlows!$G$6:$G$309,"Ongoing") -> 0 | D7: =SUMIFS(CashFlows!$E$6:$E$309,CashFlows!$A$6:$A$309,">="&DATE(VALUE(MID($A7,4,4)),(VALUE(MID($A7,2,1))-1)*3+1,1),CashFlows!$A$6:$A$309,"<="&DATE(VALUE(MID($A7,4,4)),VALUE(MID($A7,2,1))*3+1,0),CashFlows!$D$6:$D$309,"<>Capital Call",CashFlows!$D$6:$D$309,"<>") -> 0 | E7: =B7+C7+D7 -> -15000 | F7: =F6+E7 -> -175000
A8: Q1 2026 | B8: =SUMIFS(CashFlows!$E$6:$E$309,CashFlows!$A$6:$A$309,">="&DATE(VALUE(MID($A8,4,4)),(VALUE(MID($A8,2,1))-1)*3+1,1),CashFlows!$A$6:$A$309,"<="&DATE(VALUE(MID($A8,4,4)),VALUE(MID($A8,2,1))*3+1,0),CashFlows!$G$6:$G$309,"Initial") -> -100000 | C8: =SUMIFS(CashFlows!$E$6:$E$309,CashFlows!$A$6:$A$309,">="&DATE(VALUE(MID($A8,4,4)),(VALUE(MID($A8,2,1))-1)*3+1,1),CashFlows!$A$6:$A$309,"<="&DATE(VALUE(MID($A8,4,4)),VALUE(MID($A8,2,1))*3+1,0),CashFlows!$G$6:$G$309,"Ongoing") -> 0 | D8: =SUMIFS(CashFlows!$E$6:$E$309,CashFlows!$A$6:$A$309,">="&DATE(VALUE(MID($A8,4,4)),(VALUE(MID($A8,2,1))-1)*3+1,1),CashFlows!$A$6:$A$309,"<="&DATE(VALUE(MID($A8,4,4)),VALUE(MID($A8,2,1))*3+1,0),CashFlows!$D$6:$D$309,"<>Capital Call",CashFlows!$D$6:$D$309,"<>") -> 0 | E8: =B8+C8+D8 -> -100000 | F8: =F7+E8 -> -275000
A9: Q2 2026 | B9: =SUMIFS(CashFlows!$E$6:$E$309,CashFlows!$A$6:$A$309,">="&DATE(VALUE(MID($A9,4,4)),(VALUE(MID($A9,2,1))-1)*3+1,1),CashFlows!$A$6:$A$309,"<="&DATE(VALUE(MID($A9,4,4)),VALUE(MID($A9,2,1))*3+1,0),CashFlows!$G$6:$G$309,"Initial") -> -45000 | C9: =SUMIFS(CashFlows!$E$6:$E$309,CashFlows!$A$6:$A$309,">="&DATE(VALUE(MID($A9,4,4)),(VALUE(MID($A9,2,1))-1)*3+1,1),CashFlows!$A$6:$A$309,"<="&DATE(VALUE(MID($A9,4,4)),VALUE(MID($A9,2,1))*3+1,0),CashFlows!$G$6:$G$309,"Ongoing") -> -12500 | D9: =SUMIFS(CashFlows!$E$6:$E$309,CashFlows!$A$6:$A$309,">="&DATE(VALUE(MID($A9,4,4)),(VALUE(MID($A9,2,1))-1)*3+1,1),CashFlows!$A$6:$A$309,"<="&DATE(VALUE(MID($A9,4,4)),VALUE(MID($A9,2,1))*3+1,0),CashFlows!$D$6:$D$309,"<>Capital Call",CashFlows!$D$6:$D$309,"<>") -> 750 | E9: =B9+C9+D9 -> -56750 | F9: =F8+E9 -> -331750
